Workbook
Name cause: #REF!
Name cause: #REF!
Name Comments: #REF!
Name Comments: #REF!
Name Domain: #REF!
Name Domain: #REF!
Name Ltst_TestLog: "'Test log'"
Name NullOption: #REF!
Name NullOption: #REF!
Name Severity: #REF!
Name Severity: #REF!
Name State_of_Origin: #REF!
Name State_of_Origin: #REF!
Name ValidDepts2: [1]Dropdown용!$A$1:$A$2
Name 변경여부: #REF!
Name 변경여부: #REF!
Name 속성유형: #REF!
Name 속성유형: #REF!
Name 수정여부: [2]기준표!$A$10:$A$14
Name 작업상태: #REF!
Name 작업상태: #REF!
Name 작업상태: #REF!
Name 작업상태: [3]코드값!$A$4:$A$8
Name 작업상태: [3]코드값!$A$4:$A$8
Name 작업상태: #REF!
Name 작업상태2: #REF!
Name 작업상태3: #REF!
Name 적용여부: [2]기준표!$A$4:$A$6
Name 추가변경여부: #REF!
Name 추가변경여부: #REF!
Name 카드관리부서: #REF!
Name 카드관리부서: #REF!
Name 카드캐피탈구분: #REF!
Name 카드캐피탈구분: #REF!
Name 캐피탈관리부서: #REF!
Name 캐피탈관리부서: #REF!

Sheet 표지
A4: WBS
A6: 투자자산관리시스템 재구축(1단계)

Sheet 개정이력
B2: WBS
B3: 범위 | E3: 프로젝트관리 | K3: 문서코드 | N3: PP01
B4: 단계 | E4: 준비 | K4: 작 성 자 | N4: 곽병철 | T4: 작 성 일 | W4: =MAX(D9:G30) -> 46150
B7: 개정 이력
B8: 버전 | D8: 변경일 | H8: 변경사유 | K8: 변경내용 | W8: 작성자 | Z8: 승인자
B9: 0.1 | D9: 46139 | H9: 최초작성 | K9: 최초작성 | W9: 곽병철 | Z9: 이동현
B10: 0.3 | D10: 46150 | H10: 착수보고 | K10: 착수보고용 | W10: 곽병철 | Z10: 이동현
B32: * 문서 버전 : 최초 발주사 승인 버전은 1.0으로 시작하되, 변경 사항이 오류수정 등 미비할 경우
B33: 소수점 자리, 내용 추가 등 중대한 변경이 발생한 경우는 정수 자리의 버전번호 증가로 구분
B34: * 변경 사유 : 최초작성/내용수정/내용추가/내용삭제로 구분하여 기입

Sheet 진척율보고서
A1: 프로젝트 진척률 보고서
A3: 1. 프로젝트 명 | C3: 투자자산관리시스템 재구축(1단계) | G3: 실적 측정 기준일 | H3: 46269
A4: 2. 프로젝트 일정 | C4: 누적 진척률 계산기간 | E4: 업무별 가중치
C5: 시작일 | D5: 종료일 | E5: =C9 -> 사업관리 | F5: =C10 -> 프로젝트 진행관리 | I5: 가중치합
C6: 46139 | D6: 46564 | E6: 0.3 | F6: 0.7 | I6: =SUM(E6:H6) -> 1
A7: 3. 프로젝트 진척율 | C7: 구분 | D7: 금주 누적 진척률 | H7: 비 고
D8: 계획진척률 | E8: 실적진척률 | F8: 진척달성률 | G8: 차이 | H8: ○ 실적 진척률 부여 기준(각 Task)
C9: 사업관리 | D9: ='1. 사업관리'!M3 -> 0.48181818 | E9: ='1. 사업관리'!Q3 -> 0.48181818 | F9: =E9/D9 -> 1 | G9: =E9-D9 -> 0 | H9: - 미착수 : 0% - 착수 : 20% - 수행(Draft 작성) : 70% - PL검토 : 90% - PM확인 : 100%
C10: 프로젝트 진행관리 | D10: ='2. 프로젝트 진행관리'!M3 -> 0.060283688 | E10: ='2. 프로젝트 진행관리'!Q3 -> 0.060283688 | F10: =E10/D10 -> 1 | G10: =E10-D10 -> 0
C11: 전체 | D11: =D9*E6+D10*F6 -> 0.18674404 | E11: =E9*E6+E10*F6 -> 0.18674404 | F11: =E11/D11 -> 1 | G11: =E11-D11 -> 0 | H11: ○ 업무별 가중치의 합은 반드시 100%

Sheet 1. 사업관리
A1: 1. 사업관리(PMO) WBS
K3: 계획진척률(누적) | M3: =COUNTIF(N6:N184, "100%")/COUNT(K6:K184) -> 0.48181818 | O3: 실적진척률(누적) | Q3: =COUNTIF(P6:P184, "100%")/COUNT(K6:K184) -> 0.48181818
K4: 계획 | O4: 실적
A5: NO | B5: 단계 | C5: Activity | D5: Task | F5: Leaf Task | G5: Task 속성 | H5: 산출물 | I5: 자원 | J5: 진행상태 | K5: 계획시작일 | L5: 계획종료일 | M5: 기간 | N5: 계획진척률 | O5: 실적 진척 상태 | P5: 실적 진척률 | Q5: 실제시작일 | R5: 예상종료일 | S5: 실제종료일
A6: 1 | B6: 주요 Milestone 관리 | J6: =IF(OR(ISBLANK($K$11), ISBLANK($L6)),"",IF($P6<$N6, "지연", "")) | M6: =IF(OR(ISBLANK($K6), ISBLANK($L6)),"",NETWORKDAYS($K6,$L6))
A7: 2 | C7: 계약서류준비 | J7: =IF(OR(ISBLANK($K$11), ISBLANK($L7)),"",IF($P7<$N7, "지연", "")) | M7: =IF(OR(ISBLANK($K7), ISBLANK($L7)),"",NETWORKDAYS($K7,$L7)) | P7: =IF($O7="PM확인(100%)", 1, IF($O7="PL검토(90%)", 0.9, IF($O7="수행(70%)", 0.7, IF($O7="착수(20%)", 0.2, IF($O7="미착수(0%)",0,"")))))
A8: 3 | D8: 계약서류 | F8: ○ | G8: 작업 | H8: 계약서 | I8: 기획팀 | J8: =IF(OR(ISBLANK($K8), ISBLANK($L8)),"",IF($P8<$N8, "지연", "")) | K8: 46139 | L8: 46139 | M8: =IF(OR(ISBLANK($K8), ISBLANK($L8)),"",NETWORKDAYS($K8,$L8)) -> 1 | N8: 1 | O8: PM확인(100%) | P8: =IF($O8="PM확인(100%)", 1, IF($O8="PL검토(90%)", 0.9, IF($O8="수행(70%)", 0.7, IF($O8="착수(20%)", 0.2, IF($O8="미착수(0%)",0,""))))) -> 1 | Q8: 46139 | R8: 46139 | S8: 46139
A9: 4 | C9: 정기/비정기 보고 및 워크숍 | J9: =IF(OR(ISBLANK($K9), ISBLANK($L9)),"",IF($P9<$N9, "지연", "")) | M9: =IF(OR(ISBLANK($K9), ISBLANK($L9)),"",NETWORKDAYS($K9,$L9))
A10: 5 | D10: 정기 보고 | J10: =IF(OR(ISBLANK($K10), ISBLANK($L10)),"",IF($P10<$N10, "지연", "")) | M10: =IF(OR(ISBLANK($K10), ISBLANK($L10)),"",NETWORKDAYS($K10,$L10))
A11: 6 | E11: 착수보고 | F11: ○ | G11: 작업 | H11: 착수보고서 | I11: 기획팀 | J11: =IF(OR(ISBLANK($K11), ISBLANK($L11)),"",IF($P11<$N11, "지연", "")) | K11: 46155 | L11: 46155 | M11: =IF(OR(ISBLANK($K11), ISBLANK($L11)),"",NETWORKDAYS($K11,$L11)) -> 1 | N11: 1 | O11: PM확인(100%) | P11: =IF($O11="PM확인(100%)", 1, IF($O11="PL검토(90%)", 0.9, IF($O11="수행(70%)", 0.7, IF($O11="착수(20%)", 0.2, IF($O11="미착수(0%)",0,""))))) -> 1 | Q11: 46155 | R11: 46155 | S11: 46155
A12: 7 | E12: 중간보고 | F12: ○ | G12: 작업 | H12: 중간보고서 | I12: 기획팀 | J12: =IF(OR(ISBLANK($K12), ISBLANK($L12)),"",IF($P12<$N12, "지연", "")) | K12: 46356 | L12: 46356 | M12: =IF(OR(ISBLANK($K12), ISBLANK($L12)),"",NETWORKDAYS($K12,$L12)) -> 1 | O12: 미착수(0%) | P12: =IF($O12="PM확인(100%)", 1, IF($O12="PL검토(90%)", 0.9, IF($O12="수행(70%)", 0.7, IF($O12="착수(20%)", 0.2, IF($O12="미착수(0%)",0,""))))) -> 0
A13: 8 | E13: 완료보고 | F13: ○ | G13: 작업 | H13: 완료보고서 | I13: 기획팀 | J13: =IF(OR(ISBLANK($K13), ISBLANK($L13)),"",IF($P13<$N13, "지연", "")) | K13: 46563 | L13: 46563 | M13: =IF(OR(ISBLANK($K13), ISBLANK($L13)),"",NETWORKDAYS($K13,$L13)) -> 1 | O13: 미착수(0%) | P13: =IF($O13="PM확인(100%)", 1, IF($O13="PL검토(90%)", 0.9, IF($O13="수행(70%)", 0.7, IF($O13="착수(20%)", 0.2, IF($O13="미착수(0%)",0,""))))) -> 0
A14: 9 | D14: 비정기 보고 | J14: =IF(OR(ISBLANK($K14), ISBLANK($L14)),"",IF($P14<$N14, "지연", "")) | M14: =IF(OR(ISBLANK($K14), ISBLANK($L14)),"",NETWORKDAYS($K14,$L14))
A15: 10 | E15: 요구분석 진행상황 보고 | F15: ○ | G15: 작업 | I15: 기획팀 | J15: =IF(OR(ISBLANK($K15), ISBLANK($L15)),"",IF($P15<$N15, "지연", "")) | M15: =IF(OR(ISBLANK($K15), ISBLANK($L15)),"",NETWORKDAYS($K15,$L15)) | O15: 미착수(0%) | P15: =IF($O15="PM확인(100%)", 1, IF($O15="PL검토(90%)", 0.9, IF($O15="수행(70%)", 0.7, IF($O15="착수(20%)", 0.2, IF($O15="미착수(0%)",0,""))))) -> 0
A16: 11 | E16: 설계단계 진행상황 보고 | F16: ○ | G16: 작업 | I16: 기획팀 | J16: =IF(OR(ISBLANK($K16), ISBLANK($L16)),"",IF($P16<$N16, "지연", "")) | M16: =IF(OR(ISBLANK($K16), ISBLANK($L16)),"",NETWORKDAYS($K16,$L16)) | O16: 미착수(0%) | P16: =IF($O16="PM확인(100%)", 1, IF($O16="PL검토(90%)", 0.9, IF($O16="수행(70%)", 0.7, IF($O16="착수(20%)", 0.2, IF($O16="미착수(0%)",0,""))))) -> 0
A17: 12 | E17: 구축단계 진행상황 보고 | F17: ○ | G17: 작업 | I17: 기획팀 | J17: =IF(OR(ISBLANK($K17), ISBLANK($L17)),"",IF($P17<$N17, "지연", "")) | M17: =IF(OR(ISBLANK($K17), ISBLANK($L17)),"",NETWORKDAYS($K17,$L17)) | O17: 미착수(0%) | P17: =IF($O17="PM확인(100%)", 1, IF($O17="PL검토(90%)", 0.9, IF($O17="수행(70%)", 0.7, IF($O17="착수(20%)", 0.2, IF($O17="미착수(0%)",0,""))))) -> 0
A18: 13 | C18: 범위 확정 | J18: =IF(OR(ISBLANK($K18), ISBLANK($L18)),"",IF($P18<$N18, "지연", "")) | M18: =IF(OR(ISBLANK($K18), ISBLANK($L18)),"",NETWORKDAYS($K18,$L18))
A19: 14 | D19: 사업수행계획서 승인 | F19: ○ | G19: 작업 | H19: 사업수행계획서 | I19: 개발팀/기획팀 | J19: =IF(OR(ISBLANK($K19), ISBLANK($L19)),"",IF($P19<$N19, "지연", "")) | K19: 46153 | L19: 46157 | M19: =IF(OR(ISBLANK($K19), ISBLANK($L19)),"",NETWORKDAYS($K19,$L19)) -> 5 | N19: 1 | O19: PM확인(100%) | P19: =IF($O19="PM확인(100%)", 1, IF($O19="PL검토(90%)", 0.9, IF($O19="수행(70%)", 0.7, IF($O19="착수(20%)", 0.2, IF($O19="미착수(0%)",0,""))))) -> 1 | Q19: 46153 | R19: 46157 | S19: 46157
A20: 15 | D20: 요구사항정의서 승인 | F20: ○ | G20: 작업 | H20: 요구사항정의서 | I20: 기획팀 | J20: =IF(OR(ISBLANK($K20), ISBLANK($L20)),"",IF($P20<$N20, "지연", "")) | K20: 46153 | L20: 46157 | M20: =IF(OR(ISBLANK($K20), ISBLANK($L20)),"",NETWORKDAYS($K20,$L20)) -> 5 | N20: 1 | O20: PM확인(100%) | P20: =IF($O20="PM확인(100%)", 1, IF($O20="PL검토(90%)", 0.9, IF($O20="수행(70%)", 0.7, IF($O20="착수(20%)", 0.2, IF($O20="미착수(0%)",0,""))))) -> 1 | Q20: 46153 | R20: 46157 | S20: 46157
A21: 16 | D21: 과업대비표 작성 및 Update | M21: =IF(OR(ISBLANK($K21), ISBLANK($L21)),"",NETWORKDAYS($K21,$L21))
A22: 17 | E22: 과업대비표 작성 | F22: ○ | G22: 작업 | H22: 과업대비표 | I22: 기획팀 | J22: =IF(OR(ISBLANK($K22), ISBLANK($L22)),"",IF($P22<$N22, "지연", "")) | K22: 46160 | L22: 46171 | M22: =IF(OR(ISBLANK($K22), ISBLANK($L22)),"",NETWORKDAYS($K22,$L22)) -> 10 | N22: 1 | O22: PM확인(100%) | P22: =IF($O22="PM확인(100%)", 1, IF($O22="PL검토(90%)", 0.9, IF($O22="수행(70%)", 0.7, IF($O22="착수(20%)", 0.2, IF($O22="미착수(0%)",0,""))))) -> 1 | Q22: 46160 | R22: 46171 | S22: 46171
A23: 18 | E23: 분석단계 Update | F23: ○ | G23: 작업 | H23: 과업대비표 | I23: 개발팀 | J23: =IF(OR(ISBLANK($K23), ISBLANK($L23)),"",IF($P23<$N23, "지연", "")) | K23: 46174 | L23: 46199 | M23: =IF(OR(ISBLANK($K23), ISBLANK($L23)),"",NETWORKDAYS($K23,$L23)) -> 20 | N23: 1 | O23: PM확인(100%) | P23: =IF($O23="PM확인(100%)", 1, IF($O23="PL검토(90%)", 0.9, IF($O23="수행(70%)", 0.7, IF($O23="착수(20%)", 0.2, IF($O23="미착수(0%)",0,""))))) -> 1 | Q23: 46174 | R23: 46199 | S23: 46199
A24: 19 | E24: 설계단계 Update | F24: ○ | G24: 작업 | H24: 과업대비표/요구사항추적매트릭스 | I24: 개발팀 | J24: =IF(OR(ISBLANK($K24), ISBLANK($L24)),"",IF($P24<$N24, "지연", "")) | M24: =IF(OR(ISBLANK($K24), ISBLANK($L24)),"",NETWORKDAYS($K24,$L24)) | O24: 미착수(0%) | P24: =IF($O24="PM확인(100%)", 1, IF($O24="PL검토(90%)", 0.9, IF($O24="수행(70%)", 0.7, IF($O24="착수(20%)", 0.2, IF($O24="미착수(0%)",0,""))))) -> 0
A25: 20 | E25: 구축단계 Update | F25: ○ | G25: 작업 | H25: 과업대비표/검사기준서/요구사항추적매트릭스 | I25: 개발팀 | J25: =IF(OR(ISBLANK($K25), ISBLANK($L25)),"",IF($P25<$N25, "지연", "")) | M25: =IF(OR(ISBLANK($K25), ISBLANK($L25)),"",NETWORKDAYS($K25,$L25)) | O25: 미착수(0%) | P25: =IF($O25="PM확인(100%)", 1, IF($O25="PL검토(90%)", 0.9, IF($O25="수행(70%)", 0.7, IF($O25="착수(20%)", 0.2, IF($O25="미착수(0%)",0,""))))) -> 0
A26: 21 | C26: 대금신청 | M26: =IF(OR(ISBLANK($K26), ISBLANK($L26)),"",NETWORKDAYS($K26,$L26))
A27: 22 | D27: 선금신청(30%) | F27: ○ | G27: 작업 | H27: 대금신청서, 선금보증서 | I27: 경영지원/기획팀 | J27: =IF(OR(ISBLANK($K27), ISBLANK($L27)),"",IF($P27<$N27, "지연", "")) | K27: 46168 | L27: 46168 | M27: =IF(OR(ISBLANK($K27), ISBLANK($L27)),"",NETWORKDAYS($K27,$L27)) -> 1 | N27: 1 | O27: PM확인(100%) | P27: =IF($O27="PM확인(100%)", 1, IF($O27="PL검토(90%)", 0.9, IF($O27="수행(70%)", 0.7, IF($O27="착수(20%)", 0.2, IF($O27="미착수(0%)",0,""))))) -> 1 | Q27: 46168 | R27: 46168 | S27: 46168
A28: 23 | D28: 중도금신청(30%) | F28: ○ | G28: 작업 | H28: 대금신청서, 중도금보증서 | I28: 경영지원/기획팀 | J28: =IF(OR(ISBLANK($K28), ISBLANK($L28)),"",IF($P28<$N28, "지연", "")) | M28: =IF(OR(ISBLANK($K28), ISBLANK($L28)),"",NETWORKDAYS($K28,$L28)) | O28: 미착수(0%) | P28: =IF($O28="PM확인(100%)", 1, IF($O28="PL검토(90%)", 0.9, IF($O28="수행(70%)", 0.7, IF($O28="착수(20%)", 0.2, IF($O28="미착수(0%)",0,""))))) -> 0
A29: 24 | D29: 잔금신청(40%) | F29: ○ | G29: 작업 | H29: 대금신청서, 잔금보증서, 준공신고서 | I29: 경영지원/기획팀 | J29: =IF(OR(ISBLANK($K29), ISBLANK($L29)),"",IF($P29<$N29, "지연", "")) | M29: =IF(OR(ISBLANK($K29), ISBLANK($L29)),"",NETWORKDAYS($K29,$L29)) | O29: 미착수(0%) | P29: =IF($O29="PM확인(100%)", 1, IF($O29="PL검토(90%)", 0.9, IF($O29="수행(70%)", 0.7, IF($O29="착수(20%)", 0.2, IF($O29="미착수(0%)",0,""))))) -> 0
A30: 25 | C30: 시스템 오픈 | J30: =IF(OR(ISBLANK($K30), ISBLANK($L30)),"",IF($P30<$N30, "지연", "")) | M30: =IF(OR(ISBLANK($K30), ISBLANK($L30)),"",NETWORKDAYS($K30,$L30))
A31: 26 | D31: 1차 오픈 | F31: ○ | G31: 작업 | H31: 시범서비스 오픈 | J31: =IF(OR(ISBLANK($K31), ISBLANK($L31)),"",IF($P31<$N31, "지연", "")) | K31: 46538 | L31: 46538 | M31: =IF(OR(ISBLANK($K31), ISBLANK($L31)),"",NETWORKDAYS($K31,$L31)) -> 1 | O31: 미착수(0%) | P31: =IF($O31="PM확인(100%)", 1, IF($O31="PL검토(90%)", 0.9, IF($O31="수행(70%)", 0.7, IF($O31="착수(20%)", 0.2, IF($O31="미착수(0%)",0,""))))) -> 0
A32: 27 | D32: 2차 오픈 | F32: ○ | G32: 작업 | H32: 정식서비스 오픈 | J32: =IF(OR(ISBLANK($K32), ISBLANK($L32)),"",IF($P32<$N32, "지연", "")) | K32: 46563 | L32: 46563 | M32: =IF(OR(ISBLANK($K32), ISBLANK($L32)),"",NETWORKDAYS($K32,$L32)) -> 1 | O32: 미착수(0%) | P32: =IF($O32="PM확인(100%)", 1, IF($O32="PL검토(90%)", 0.9, IF($O32="수행(70%)", 0.7, IF($O32="착수(20%)", 0.2, IF($O32="미착수(0%)",0,""))))) -> 0
A33: 28 | B33: 프로젝트 계획수립 | M33: =IF(OR(ISBLANK($K33), ISBLANK($L33)),"",NETWORKDAYS($K33,$L33))
A34: 29 | C34: 착수 | J34: =IF(OR(ISBLANK($K34), ISBLANK($L34)),"",IF($P34<$N34, "지연", "")) | M34: =IF(OR(ISBLANK($K34), ISBLANK($L34)),"",NETWORKDAYS($K34,$L34))
A35: 30 | D35: 계획수립 인력 구성 | F35: ○ | G35: 작업 | J35: =IF(OR(ISBLANK($K35), ISBLANK($L35)),"",IF($P35<$N35, "지연", "")) | K35: 46139 | L35: 46150 | M35: =IF(OR(ISBLANK($K35), ISBLANK($L35)),"",NETWORKDAYS($K35,$L35)) -> 10 | N35: 1 | O35: PM확인(100%) | P35: =IF($O35="PM확인(100%)", 1, IF($O35="PL검토(90%)", 0.9, IF($O35="수행(70%)", 0.7, IF($O35="착수(20%)", 0.2, IF($O35="미착수(0%)",0,""))))) -> 1 | Q35: 46139 | R35: 46150 | S35: 46150
A36: 31 | D36: 의사소통 채널 및 Commitment 확보 | F36: ○ | G36: 작업 | J36: =IF(OR(ISBLANK($K36), ISBLANK($L36)),"",IF($P36<$N36, "지연", "")) | K36: 46139 | L36: 46150 | M36: =IF(OR(ISBLANK($K36), ISBLANK($L36)),"",NETWORKDAYS($K36,$L36)) -> 10 | N36: 1 | O36: PM확인(100%) | P36: =IF($O36="PM확인(100%)", 1, IF($O36="PL검토(90%)", 0.9, IF($O36="수행(70%)", 0.7, IF($O36="착수(20%)", 0.2, IF($O36="미착수(0%)",0,""))))) -> 1 | Q36: 46139 | R36: 46150 | S36: 46150
A37: 32 | D37: 사무실 환경 구축 | J37: =IF(OR(ISBLANK($K37), ISBLANK($L37)),"",IF($P37<$N37, "지연", ""))
A38: 33 | E38: 사무환경 구축 | F38: ○ | G38: 작업 | J38: =IF(OR(ISBLANK($K38), ISBLANK($L38)),"",IF($P38<$N38, "지연", "")) | K38: 46139 | L38: 46150 | M38: =IF(OR(ISBLANK($K38), ISBLANK($L38)),"",NETWORKDAYS($K38,$L38)) -> 10 | N38: 1 | O38: PM확인(100%) | P38: =IF($O38="PM확인(100%)", 1, IF($O38="PL검토(90%)", 0.9, IF($O38="수행(70%)", 0.7, IF($O38="착수(20%)", 0.2, IF($O38="미착수(0%)",0,""))))) -> 1 | Q38: 46139 | R38: 46150 | S38: 46150
A39: 34 | E39: 프로젝트 관리 도구 설치 | F39: ○ | G39: 작업 | H39: 개발환경 구축, SVN구축 | I39: 개발팀 | J39: =IF(OR(ISBLANK($K39), ISBLANK($L39)),"",IF($P39<$N39, "지연", "")) | K39: 46139 | L39: 46150 | M39: =IF(OR(ISBLANK($K39), ISBLANK($L39)),"",NETWORKDAYS($K39,$L39)) -> 10 | N39: 1 | O39: PM확인(100%) | P39: =IF($O39="PM확인(100%)", 1, IF($O39="PL검토(90%)", 0.9, IF($O39="수행(70%)", 0.7, IF($O39="착수(20%)", 0.2, IF($O39="미착수(0%)",0,""))))) -> 1 | Q39: 46139 | R39: 46150 | S39: 46150
A40: 37 | D40: 자원 및 기간 산정 | F40: ○ | G40: 작업 | H40: 사업수행계획서 | I40: 기획팀 | J40: =IF(OR(ISBLANK($K40), ISBLANK($L40)),"",IF($P40<$N40, "지연", "")) | K40: 46139 | L40: 46150 | M40: =IF(OR(ISBLANK($K40), ISBLANK($L40)),"",NETWORKDAYS($K40,$L40)) -> 10 | N40: 1 | O40: PM확인(100%) | P40: =IF($O40="PM확인(100%)", 1, IF($O40="PL검토(90%)", 0.9, IF($O40="수행(70%)", 0.7, IF($O40="착수(20%)", 0.2, IF($O40="미착수(0%)",0,""))))) -> 1 | Q40: 46139 | R40: 46150 | S40: 46150
A41: 39 | C41: 계획수립 | J41: =IF(OR(ISBLANK($K41), ISBLANK($L41)),"",IF($P41<$N41, "지연", "")) | M41: =IF(OR(ISBLANK($K41), ISBLANK($L41)),"",NETWORKDAYS($K41,$L41))
...

Sheet 2. 프로젝트 진행관리
A1: 2. 프로젝트 진행관리 WBS
K3: 계획진척률(누적) | M3: =COUNTIF(N7:N377, "100%")/COUNT(K7:K377) -> 0.060283688 | O3: 실적진척률(누적) | Q3: =COUNTIF(P7:P377, "100%")/COUNT(K7:K377) -> 0.060283688
K4: 계획 | O4: 실적
A5: NO | B5: 단계 | C5: Activity | D5: Task | F5: Leaf Task | G5: Task 속성 | H5: 산출물 | I5: 자원 | J5: 진행상태 | K5: 계획시작일 | L5: 계획종료일 | M5: 기간 | N5: 계획진척률 | O5: 실적 진척상태 | P5: 실적 진척률 | Q5: 실제시작일 | R5: 예상종료일 | S5: 실제종료일
B6: Web개발 방법론 | J6: =IF(OR(ISBLANK(#REF!), ISBLANK($L6)),"",IF($P6<$N6, "지연", "")) | M6: =IF(OR(ISBLANK($K6), ISBLANK($L6)),"",NETWORKDAYS($K6,$L6)) | N6: =IF(OR(ISBLANK($K6), ISBLANK($L6)), "", IF(진척율보고서!$H$3 < $K6, 0, IF(진척율보고서!$H$3 >= $L6, 1, NETWORKDAYS($K6,진척율보고서!$H$3)/$M6))) | P6: =IF($O6="PM확인(100%)", 1, IF($O6="PL검토(90%)", 0.9, IF($O6="수행(70%)", 0.7, IF($O6="착수(20%)", 0.2, IF($O6="미착수(0%)",0,"")))))
A7: 1 | B7: 분석 | J7: =IF(OR(ISBLANK(#REF!), ISBLANK($L7)),"",IF($P7<$N7, "지연", "")) | P7: =IF($O7="PM확인(100%)", 1, IF($O7="PL검토(90%)", 0.9, IF($O7="수행(70%)", 0.7, IF($O7="착수(20%)", 0.2, IF($O7="미착수(0%)",0,"")))))
A8: 2 | C8: 요구사항 분석 | J8: =IF(OR(ISBLANK(#REF!), ISBLANK($L8)),"",IF($P8<$N8, "지연", ""))
A9: 3 | D9: 기능요구사항 도출 | F9: ○ | G9: 작업 | H9: APFS-2026-120-AN01_요구사항정의서(기능)_v0.1 | I9: 기획팀 주도 / 개발팀 협업 | J9: =IF(OR(ISBLANK($K9), ISBLANK($L9)),"",IF($P9<$N9, "지연", "")) | K9: 46139 | L9: 46150 | M9: =IF(OR(ISBLANK($K9), ISBLANK($L9)),"",NETWORKDAYS($K9,$L9)) -> 10 | N9: 1 | O9: PM확인(100%) | P9: 1 | Q9: 46139 | R9: 46150 | S9: 46150
A10: 4 | D10: 비기능 요구사항 도출 | F10: ○ | G10: 작업 | H10: APFS-2026-120-AN01_요구사항정의서(비기능)_v0.1 | I10: 기획팀 주도 / 개발팀 협업 | J10: =IF(OR(ISBLANK($K10), ISBLANK($L10)),"",IF($P10<$N10, "지연", "")) | K10: 46139 | L10: 46150 | M10: =IF(OR(ISBLANK($K10), ISBLANK($L10)),"",NETWORKDAYS($K10,$L10)) -> 10 | N10: 1 | O10: PM확인(100%) | P10: 1 | Q10: 46139 | R10: 46150 | S10: 46150
A11: 5 | D11: 인터페이스 요구사항 도출 | F11: ○ | G11: 작업 | H11: APFS-2026-120-AN01_요구사항정의서(기능)_v0.1 | I11: 기획팀 주도 / 개발팀 협업 | J11: =IF(OR(ISBLANK($K11), ISBLANK($L11)),"",IF($P11<$N11, "지연", "")) | K11: 46139 | L11: 46150 | M11: =IF(OR(ISBLANK($K11), ISBLANK($L11)),"",NETWORKDAYS($K11,$L11)) -> 10 | N11: 1 | O11: PM확인(100%) | P11: 1 | Q11: 46139 | R11: 46150 | S11: 46150
A12: 6 | D12: 요구사항 정리 | F12: ○ | G12: 작업 | H12: APFS-2026-120-AN01_요구사항정의서(기능)_v0.1 | I12: 기획팀 주도 / 개발팀 협업 | J12: =IF(OR(ISBLANK($K12), ISBLANK($L12)),"",IF($P12<$N12, "지연", "")) | K12: 46139 | L12: 46150 | M12: =IF(OR(ISBLANK($K12), ISBLANK($L12)),"",NETWORKDAYS($K12,$L12)) -> 10 | N12: 1 | O12: PM확인(100%) | P12: 1 | Q12: 46139 | R12: 46150 | S12: 46150
A13: 7 | C13: 현행시스템 분석 | J13: =IF(OR(ISBLANK($K13), ISBLANK($L13)),"",IF($P13<$N13, "지연", ""))
A14: 8 | D14: 기능분해 | F14: ○ | G14: 작업 | H14: APFS-2026-120-AN03_기능분해도_v0.1 | I14: 개발팀 | J14: =IF(OR(ISBLANK($K14), ISBLANK($L14)),"",IF($P14<$N14, "지연", "")) | K14: 46153 | L14: 46213 | M14: =IF(OR(ISBLANK($K14), ISBLANK($L14)),"",NETWORKDAYS($K14,$L14)) -> 45 | N14: 1 | O14: PM확인(100%) | P14: 1 | Q14: 46153 | R14: 46213 | S14: 46213
A15: 9 | D15: DB분석 | F15: ○ | G15: 작업 | H15: APFS-2026-120-AN04_현행데이터분석서_v0.1 | I15: 개발팀 | J15: =IF(OR(ISBLANK($K15), ISBLANK($L15)),"",IF($P15<$N15, "지연", "")) | K15: 46153 | L15: 46213 | M15: =IF(OR(ISBLANK($K15), ISBLANK($L15)),"",NETWORKDAYS($K15,$L15)) -> 45 | N15: 1 | O15: PM확인(100%) | P15: 1 | Q15: 46153 | R15: 46213 | S15: 46213
A16: 10 | D16: 기술적용계획표 점검 | F16: ○ | G16: 작업 | H16: APFS-2026-120-AN05_기술적용계획표_v1.0 | I16: 개발팀 | J16: =IF(OR(ISBLANK($K16), ISBLANK($L16)),"",IF($P16<$N16, "지연", "")) | K16: 46153 | L16: 46213 | M16: =IF(OR(ISBLANK($K16), ISBLANK($L16)),"",NETWORKDAYS($K16,$L16)) -> 45 | N16: 1 | O16: PM확인(100%) | P16: 1 | Q16: 46153 | R16: 46213 | S16: 46213
A17: 11 | C17: 분석 단계 검토 | J17: =IF(OR(ISBLANK($K17), ISBLANK($L17)),"",IF($P17<$N17, "지연", ""))
A18: 12 | D18: 개발팀 Inspection | F18: ○ | G18: 작업 | H18: APFS-2026-120-AN07_분석단계품질활동결과서_v1.0 | I18: 개발팀(pm) | J18: =IF(OR(ISBLANK($K18), ISBLANK($L18)),"",IF($P18<$N18, "지연", "")) | K18: 46153 | L18: 46213 | M18: =IF(OR(ISBLANK($K18), ISBLANK($L18)),"",NETWORKDAYS($K18,$L18)) -> 45 | N18: 1 | O18: PM확인(100%) | P18: 1 | Q18: 46153 | R18: 46213 | S18: 46213
A19: 13 | D19: 고객검토 및 승인 | J19: =IF(OR(ISBLANK($K19), ISBLANK($L19)),"",IF($P19<$N19, "지연", "")) | K19: 46168 | L19: 46213 | M19: =IF(OR(ISBLANK($K19), ISBLANK($L19)),"",NETWORKDAYS($K19,$L19)) -> 34 | N19: 1 | O19: PM확인(100%) | P19: 1 | Q19: 46168 | R19: 46213 | S19: 46213
A20: 14 | E20: 고객검토 실시 | F20: ○ | G20: 작업 | H20: APFS-2026-120-AN08_발주사검토결과서_v1.0 | I20: 기획팀(pm) | J20: =IF(OR(ISBLANK($K20), ISBLANK($L20)),"",IF($P20<$N20, "지연", "")) | K20: 46168 | L20: 46213 | M20: =IF(OR(ISBLANK($K20), ISBLANK($L20)),"",NETWORKDAYS($K20,$L20)) -> 34 | N20: 1 | O20: PM확인(100%) | P20: 1 | Q20: 46168 | R20: 46213 | S20: 46213
A21: 15 | E21: 산출물 보완 | F21: ○ | G21: 작업 | H21: APFS-2026-120-AN09_시정조치계획서_v1.0 | I21: 기획팀 | J21: =IF(OR(ISBLANK($K21), ISBLANK($L21)),"",IF($P21<$N21, "지연", "")) | K21: 46168 | L21: 46213 | M21: =IF(OR(ISBLANK($K21), ISBLANK($L21)),"",NETWORKDAYS($K21,$L21)) -> 34 | N21: 1 | O21: PM확인(100%) | P21: 1 | Q21: 46168 | R21: 46213 | S21: 46213
A22: 16 | D22: 요구사항추적메트릭스 Update | F22: ○ | G22: 작업 | H22: APFS-2026-120-AN06_요구사항추적표_v1.0 | I22: 개발팀/기획팀 | J22: =IF(OR(ISBLANK($K22), ISBLANK($L22)),"",IF($P22<$N22, "지연", "")) | K22: 46168 | L22: 46213 | M22: =IF(OR(ISBLANK($K22), ISBLANK($L22)),"",NETWORKDAYS($K22,$L22)) -> 34 | N22: 1 | O22: PM확인(100%) | P22: 1 | Q22: 46168 | R22: 46213 | S22: 46213
A23: 17 | D23: 다음 단계 일정 상세화 | F23: ○ | G23: 작업 | H23: APFS-2026-120-PP01_프로젝트일정계획표_v1.0 | I23: 기획팀 | J23: =IF(OR(ISBLANK($K23), ISBLANK($L23)),"",IF($P23<$N23, "지연", "")) | K23: 46168 | L23: 46213 | M23: =IF(OR(ISBLANK($K23), ISBLANK($L23)),"",NETWORKDAYS($K23,$L23)) -> 34 | N23: 1 | O23: PM확인(100%) | P23: 1 | Q23: 46168 | R23: 46213 | S23: 46213
A24: 18 | B24: 설계
A25: 19 | C25: 아키텍처정의 | J25: =IF(OR(ISBLANK($K25), ISBLANK($L25)),"",IF($P25<$N25, "지연", ""))
A26: 20 | D26: 아키텍처 정의 | F26: ○ | G26: 작업 | H26: APFS-2026-120-DE01_아키텍처정의서_v1.0 | I26: 개발팀 | J26: =IF(OR(ISBLANK($K26), ISBLANK($L26)),"",IF($P26<$N26, "지연", "")) | K26: 46209 | L26: 46290 | M26: =IF(OR(ISBLANK($K26), ISBLANK($L26)),"",NETWORKDAYS($K26,$L26)) -> 60 | N26: 0.2 | O26: 착수(20%) | P26: =IF($O26="PM확인(100%)", 1, IF($O26="PL검토(90%)", 0.9, IF($O26="수행(70%)", 0.7, IF($O26="착수(20%)", 0.2, IF($O26="미착수(0%)",0,""))))) -> 0.2 | Q26: 46209 | R26: 46297
A27: 21 | D27: 개발환경검토 | F27: ○ | G27: 작업 | H27: APFS-2026-120-DE01_아키텍처정의서_v1.0 | I27: 개발팀 | K27: 46209 | L27: 46290 | M27: =IF(OR(ISBLANK($K27), ISBLANK($L27)),"",NETWORKDAYS($K27,$L27)) -> 60 | N27: 0.2 | O27: 착수(20%) | P27: =IF($O27="PM확인(100%)", 1, IF($O27="PL검토(90%)", 0.9, IF($O27="수행(70%)", 0.7, IF($O27="착수(20%)", 0.2, IF($O27="미착수(0%)",0,""))))) -> 0.2 | Q27: 46209 | R27: 46297
A28: 22 | D28: 디자인 시안 | F28: ○ | G28: 작업 | H28: APFS-2026-120-DE04_화면스타일가이드_v1.0 | I28: 디자인팀 | K28: 46209 | L28: 46290 | M28: =IF(OR(ISBLANK($K28), ISBLANK($L28)),"",NETWORKDAYS($K28,$L28)) -> 60 | N28: 0.2 | O28: 착수(20%) | P28: =IF($O28="PM확인(100%)", 1, IF($O28="PL검토(90%)", 0.9, IF($O28="수행(70%)", 0.7, IF($O28="착수(20%)", 0.2, IF($O28="미착수(0%)",0,""))))) -> 0.2 | Q28: 46209 | R28: 46297
A29: 23 | D29: 디자인스타일가이드 | F29: ○ | G29: 작업 | H29: APFS-2026-120-DE04_화면스타일가이드_v1.0 | I29: 디자인팀 | K29: 46209 | L29: 46290 | M29: =IF(OR(ISBLANK($K29), ISBLANK($L29)),"",NETWORKDAYS($K29,$L29)) -> 60 | N29: 0.2 | O29: 착수(20%) | P29: =IF($O29="PM확인(100%)", 1, IF($O29="PL검토(90%)", 0.9, IF($O29="수행(70%)", 0.7, IF($O29="착수(20%)", 0.2, IF($O29="미착수(0%)",0,""))))) -> 0.2 | Q29: 46209 | R29: 46297
A30: 24 | D30: 개발표준 정의 | F30: ○ | G30: 작업 | H30: APFS-2026-120-DE03_개발표준정의서_v1.0 | I30: 개발팀 | J30: =IF(OR(ISBLANK($K30), ISBLANK($L30)),"",IF($P30<$N30, "지연", "")) | K30: 46209 | L30: 46290 | M30: =IF(OR(ISBLANK($K30), ISBLANK($L30)),"",NETWORKDAYS($K30,$L30)) -> 60 | N30: 0.2 | O30: 착수(20%) | P30: =IF($O30="PM확인(100%)", 1, IF($O30="PL검토(90%)", 0.9, IF($O30="수행(70%)", 0.7, IF($O30="착수(20%)", 0.2, IF($O30="미착수(0%)",0,""))))) -> 0.2 | Q30: 46209 | R30: 46297
A31: 25 | C31: 기본설계
A32: 26 | D32: 응용시스템 구조설계 | F32: ○ | G32: 작업 | H32: APFS-2026-120-DE02_어플리케이션구조도_v1.0 | I32: 개발팀 | K32: 46209 | L32: 46290 | M32: =IF(OR(ISBLANK($K32), ISBLANK($L32)),"",NETWORKDAYS($K32,$L32)) -> 60 | N32: 0.2 | O32: 착수(20%) | P32: =IF($O32="PM확인(100%)", 1, IF($O32="PL검토(90%)", 0.9, IF($O32="수행(70%)", 0.7, IF($O32="착수(20%)", 0.2, IF($O32="미착수(0%)",0,""))))) -> 0.2 | Q32: 46209 | R32: 46297
A33: 27 | D33: 프로그램 목록 정의 | F33: ○ | G33: 작업 | H33: APFS-2026-120-DE05_프로그램목록_v1.0 | I33: 개발팀 | K33: 46209 | L33: 46290 | M33: =IF(OR(ISBLANK($K33), ISBLANK($L33)),"",NETWORKDAYS($K33,$L33)) -> 60 | N33: 0.2 | O33: 착수(20%) | P33: =IF($O33="PM확인(100%)", 1, IF($O33="PL검토(90%)", 0.9, IF($O33="수행(70%)", 0.7, IF($O33="착수(20%)", 0.2, IF($O33="미착수(0%)",0,""))))) -> 0.2 | Q33: 46209 | R33: 46297
A34: 28 | D34: 화면 설계 | F34: ○ | G34: 작업 | H34: APFS-2026-120-DE06_화면설계서_v1.0 | I34: 기획팀 | K34: 46209 | L34: 46290 | M34: =IF(OR(ISBLANK($K34), ISBLANK($L34)),"",NETWORKDAYS($K34,$L34)) -> 60 | N34: 0.2 | O34: 착수(20%) | P34: =IF($O34="PM확인(100%)", 1, IF($O34="PL검토(90%)", 0.9, IF($O34="수행(70%)", 0.7, IF($O34="착수(20%)", 0.2, IF($O34="미착수(0%)",0,""))))) -> 0.2 | Q34: 46209 | R34: 46297
A35: 29 | D35: 보고서 설계 | F35: ○ | G35: 작업 | H35: APFS-2026-120-DE07_보고서설계서_v1.0 | I35: 기획팀 | K35: 46209 | L35: 46290 | M35: =IF(OR(ISBLANK($K35), ISBLANK($L35)),"",NETWORKDAYS($K35,$L35)) -> 60 | N35: 0.2 | O35: 착수(20%) | P35: =IF($O35="PM확인(100%)", 1, IF($O35="PL검토(90%)", 0.9, IF($O35="수행(70%)", 0.7, IF($O35="착수(20%)", 0.2, IF($O35="미착수(0%)",0,""))))) -> 0.2 | Q35: 46209 | R35: 46297
A36: 30 | D36: 인터페이스설계 | F36: ○ | G36: 작업 | H36: APFS-2026-120-DE08_인터페이스설계서_v1.0 | I36: 개발팀 | K36: 46209 | L36: 46290 | M36: =IF(OR(ISBLANK($K36), ISBLANK($L36)),"",NETWORKDAYS($K36,$L36)) -> 60 | N36: 0.2 | O36: 착수(20%) | P36: =IF($O36="PM확인(100%)", 1, IF($O36="PL검토(90%)", 0.9, IF($O36="수행(70%)", 0.7, IF($O36="착수(20%)", 0.2, IF($O36="미착수(0%)",0,""))))) -> 0.2 | Q36: 46209 | R36: 46297
A37: 31 | C37: 표준화 계획수립
A38: 32 | D38: 표준화 계획수립 | F38: ○ | G38: 작업 | H38: APFS-2026-120-DE09_DB표준화계획서_v1.0 | I38: 개발팀 | K38: 46209 | L38: 46290 | M38: =IF(OR(ISBLANK($K38), ISBLANK($L38)),"",NETWORKDAYS($K38,$L38)) -> 60 | N38: 0.2 | O38: 착수(20%) | P38: =IF($O38="PM확인(100%)", 1, IF($O38="PL검토(90%)", 0.9, IF($O38="수행(70%)", 0.7, IF($O38="착수(20%)", 0.2, IF($O38="미착수(0%)",0,""))))) -> 0.2 | Q38: 46209 | R38: 46297
A39: 33 | C39: 표준항목 개발/확정 | P39: =IF($O39="PM확인(100%)", 1, IF($O39="PL검토(90%)", 0.9, IF($O39="수행(70%)", 0.7, IF($O39="착수(20%)", 0.2, IF($O39="미착수(0%)",0,"")))))
A40: 34 | D40: 표준항목개발 | F40: ○ | G40: 작업 | H40: APFS-2026-120-DE10_표준항목정의서_v1.0 | I40: 개발팀/기획팀 | K40: 46209 | L40: 46290 | M40: =IF(OR(ISBLANK($K40), ISBLANK($L40)),"",NETWORKDAYS($K40,$L40)) -> 60 | N40: 1 | O40: PM확인(100%) | P40: =IF($O40="PM확인(100%)", 1, IF($O40="PL검토(90%)", 0.9, IF($O40="수행(70%)", 0.7, IF($O40="착수(20%)", 0.2, IF($O40="미착수(0%)",0,""))))) -> 1 | Q40: 46209 | R40: 46290
A41: 35 | D41: 표준용어개발 | F41: ○ | G41: 작업 | H41: APFS-2026-120-DE11_표준용어정의서_v1.0 | I41: 개발팀/기획팀 | K41: 46209 | L41: 46290 | M41: =IF(OR(ISBLANK($K41), ISBLANK($L41)),"",NETWORKDAYS($K41,$L41)) -> 60 | N41: 1 | O41: PM확인(100%) | P41: =IF($O41="PM확인(100%)", 1, IF($O41="PL검토(90%)", 0.9, IF($O41="수행(70%)", 0.7, IF($O41="착수(20%)", 0.2, IF($O41="미착수(0%)",0,""))))) -> 1 | Q41: 46209 | R41: 46290
...

Sheet 메뉴구성도
A1: 새로운 메뉴 구성(이대표님 작성) | D1: 현 시스템 매칭 | H1: 현 시스템 매칭 | L1: 현 시스템 매칭 | P1: 현 시스템 매칭 | T1: 현 시스템 매칭 | Y1: html
A2: 투자자산관리 | D2: ffms | E2: 조기경보 | H2: risk | I2: 자펀드 보고 | L2: report | M2: 회계 | P2: 회계 | Q2: 부처보고 | T2: brief / trust | V2: 로그인
B4: 모태펀드 관리 | D4: ffms > 모태펀드 관리 | F4: 조기경보 | H4: risk > 조기경보 | J4: 운영기관정보 | L4: 신규(현행 없음) | N4: 기초관리 | P4: 회계 > 기초관리 | R4: 모태펀드 | T4: brief > 모태펀드 | W4: 로그인
C5: 자펀드 공고 정보관리 | D5: ffms > 모태펀드 관리 > 자펀드 공고 정보관리 | G5: 조기경보 관리 | H5: risk > 조기경보 > 조기경보 조회 | K5: 운용사별 공통코드 정보 | L5: 신규(현행 없음) | O5: 계정과목 관리 | P5: 회계 > 기초관리 > 계정과목 관리 | S5: 연도별투자현황 | T5: brief > 모태펀드 > 연도별투자현황 | X5: 로그인 | Y5: S0_001_로그인.html
C6: 모태펀드 조성 및 출자현황 | D6: ffms > 모태펀드 관리 > 모태펀드 조성 및 출자현황 | G6: 운용사별 조기경보 조회 | H6: risk > 조기경보 > 운용사별 조기경보 조회 | K6: 운용사 정보 | L6: 신규(현행 없음) | O6: 결산양식 관리 | P6: 회계 > 기초관리 > 결산양식 관리 | R6: 등록원부 | T6: brief > 등록원부 | X6: 발급온보딩 | Y6: S0_002_발급온보딩.html
B7: 조합관리 | D7: ffms > 자펀드 관리 | G7: 자펀드별 조기경보 조회 | H7: risk > 조기경보 > 자펀드별 조기경보 조회 | K7: 운용사 인력현황 | L7: risk > 조기경보 > 운용인력 변동관리 | N7: 전표관리 | P7: 회계 > 전표관리 | S7: 등록원부관리 | T7: brief > 등록원부 > 등록원부관리 | X7: 초대온보딩 | Y7: S0_003_초대온보딩_운용사.html
C8: 자펀드정보관리 | D8: ffms > 자펀드 관리 > 자펀드 관리 / risk > 기초정보 > 자펀드 정보 관리 | G8: 법률/규약위반사항 관리 | H8: risk > 조기경보 > 법률/규약위반사항 관리 | K8: 공동GP펀드별 인력현황 | L8: 신규(현행 없음) | O8: 일반전표 관리 | P8: 회계 > 전표관리 > 일반전표 관리
C9: 조합원정보조회 | D9: ffms > 자펀드 관리 > 조합원정보등록 | G9: 운용사 주주변동관리 | H9: risk > 조기경보 > 운용사 주주변동관리 | K9: 운용사 계정과목 | L9: 신규(현행 없음) | O9: 삭제전표 관리 | P9: 회계 > 전표관리 > 삭제전표 관리
C10: 자편드별조합원조회 | D10: ffms > 자펀드 관리 > 자펀드별조합원관리 | G10: 운용사 소송관리 | H10: risk > 조기경보 > 운용사 소송관리 | K10: 운용사 재무정보 | L10: ffms > 투자기업정보 > 운용사별 재무제표 / ffms > 모니터링 > 운용사 재무정보 조회 | O10: 미결계정 관리 | P10: 회계 > 전표관리 > 미결계정 관리 | Q10: 수탁보고 | T10: trust
B11: 사후보고관리 | D11: ffms > 사후보고관리 | G11: 운용인력 변동관리 | H11: risk > 조기경보 > 운용인력 변동관리 | K11: 운용사 정량지표 보고내역 | L11: risk > 기초정보 > 운용사 정량지표 관리 | O11: 전표증빙 미첨부 관리 | P11: 회계 > 전표관리 > 전표증빙 미첨부 관리
C12: 투심보고 확정 및 승인 | D12: ffms > 사후보고관리 > 투자심의 관리 | G12: 조기경보 결과정보 관리 | H12: risk > 조기경보 > 조기경보 결과정보 관리 | J12: 조합정보 | L12: 신규(현행 없음) | O12: 일마감 | P12: 회계 > 전표관리 > 일마감 | R12: 자펀드 수탁 | T12: trust > 자펀드 수탁
C13: 투심보고 통계 | D13: ffms > 통계 > 투심승인정보조회 | G13: 조기경보 전월 비교 조회 | H13: risk > 조기경보 > 조기경보 전월 비교 조회 | K13: 조합정보 | L13: ffms > 자펀드 관리 > 자펀드 관리 | O13: 전표검색 | P13: 회계 > 전표관리 > 전표검색 | S13: 실물자료관리(업로드) | T13: trust > 자펀드 수탁 > 실물자료관리(업로드)
C14: 내부 투자심의 구성관리 | D14: 신규(현행 없음) | F14: 기업정보 | H14: risk > 기업정보 | K14: 조합원정보조회 | L14: ffms > 자펀드 관리 > 조합원정보등록 / 자펀드별조합원관리 | N14: 장부조회 | P14: 회계 > 장부조회 | S14: 실물검증비교조회 | T14: trust > 자펀드 수탁 > 실물검증비교조회
C15: 체크리스트 관리 | D15: 신규(현행 없음) | G15: 투자기업정보(NICE평가정보) | H15: risk > 기업정보 > 기업개요 / 업체사업장정보 / 법정관리및화의정보 | K15: 조합 투자운용인력 | L15: risk > 조기경보 > 운용인력 변동관리 | O15: 일/월계표 | P15: 회계 > 장부조회 > 일/월계표 | S15: 유가증권관리(업로드) | T15: 신규(현행 없음)
C16: 수시보고 확인 | D16: ffms > 사후보고관리 > 수시보고 / report > 일일보고조회 > 조합별 수시보고 현황 | G16: 투자기업신용정보 조회 | H16: risk > 기업정보 > 신용등급 / 현금흐름등급 | K16: 조합 월별/반기별 보고현황 | L16: report > 월간보고조회 > 조합별 월간보고 현황 / report > 반기보고조회 > 조합별 반기보고 현황 | O16: 계정별보조부 | P16: 회계 > 장부조회 > 계정별보조부 | S16: 유가증권비교조회 | T16: 신규(현행 없음)
C17: 정기보고 | D17: ffms > 사후보고관리 > 정기보고 / ffms > 통계 > 정기보고회수내역 | F17: 자펀드정보 | H17: risk > 기초정보 | K17: 조합 재무현황 | L17: 신규(현행 없음) | O17: 총계정원장 | P17: 회계 > 장부조회 > 총계정원장 | S17: 공통코드조회 | T17: trust > 자펀드 수탁 > 공통코드조회
C18: 조합원총회 | D18: ffms > 사후보고관리 > 조합원총회 | G18: 운용사 정량지표 관리 | H18: risk > 기초정보 > 운용사 정량지표 관리 | K18: 조합 계좌현황 | L18: 신규(현행 없음) | O18: 재무상태표 | P18: 회계 > 장부조회 > 재무상태표 | S18: 자펀드코드 조회 | T18: trust > 자펀드 수탁 > 자펀드코드 조회
C19: 조합예상자금요청보고 | D19: ffms > 사후보고관리 > 조합예상자금요청보고 | G19: 운용사 유형별 정량지표 변동 조회 | H19: risk > 통계정보 > 운용사 유형별 정량지표 변동 | K19: 조합Call 요청일정 및 보고 | L19: ffms > 사후보고관리 > 조합예상자금요청보고 | O19: 손익계산서 | P19: 회계 > 장부조회 > 손익계산서 | R19: 모태펀드 수탁 | T19: trust > 모태펀드 수탁
B20: 자펀드 관리 | D20: ffms > 자펀드 관리 | G20: 운용사 재무정보 비교 조회 | H20: risk > 기초정보 > 운용사 재무정보 비교 조회 | K20: 조합 출자/분배 현황 | L20: ffms > 자펀드 관리 > (운용사)출자배분관리 / (농금원)출자배분관리 | O20: 합계잔액시산표 | P20: 회계 > 장부조회 > 합계잔액시산표 | S20: 모태수탁 공통코드 | T20: trust > 모태펀드 수탁 > 모태수탁 공통코드
C21: 자펀드 관리 | D21: ffms > 자펀드 관리 > 자펀드 관리 | G21: 자펀드 수익률정보 비교 조회 | H21: risk > 기초정보 > 자펀드 수익률정보 비교 조회 | K21: 조합원 총회 | L21: ffms > 사후보고관리 > 조합원총회 | N21: 결산관리 | P21: 회계 > 결산관리 | S21: 계좌정보 관리 | T21: trust > 모태펀드 수탁 > 계좌정보 관리
C22: 출자/분배조회(자펀드) | D22: ffms > 자펀드 관리 > (운용사)출자배분관리 | G22: 자펀드 종합등급 변동 조회 | H22: risk > 통계정보 > 종합등급 변동 | K22: 조합 관리보수 및 성과보수 내역 | L22: ffms > 모니터링 > 관리보수관리 | O22: 결산전표 관리 | P22: 회계 > 결산관리 > 결산전표 관리 | S22: 계좌정보 비교조회 | T22: trust > 모태펀드 수탁 > 계좌정보 비교조회
C23: 출자/분배조회(농금원) | D23: ffms > 자펀드 관리 > (농금원)출자배분관리 | F23: 가치평가 | H23: risk > 가치평가 | K23: 조합 수시보고 내역 | L23: report > 일일보고조회 > 조합별 수시보고 현황 / ffms > 사후보고관리 > 수시보고 | O23: 회기생성/전기이월 | P23: 회계 > 결산관리 > 회기생성/전기이월 | S23: 입출금 정보관리 | T23: trust > 모태펀드 수탁 > 입출금 정보관리
C24: 자펀드 투자실적현황 | D24: ffms > 자펀드 관리 > 투자실적 현황(자펀드) | G24: 모태펀드 가치평가 결과조회 | H24: risk > 가치평가 > 모태펀드 가치평가 결과조회 | K24: 조합 유가증권 투자현황(상장주식) | L24: ffms > 자펀드 관리 > 자펀드수탁관리(실물검증) (검토 필요) | N24: 고정자산 | P24: 회계 > 고정자산 | S24: 입출금정보 비교조회 | T24: trust > 모태펀드 수탁 > 입출금정보 비교조회
C25: 자펀드 수탁관리 | D25: ffms > 자펀드 관리 > 자펀드수탁관리(실물검증) / 자펀드수탁관리(확정) | G25: 투자조합 가치평가 결과조회 | H25: risk > 가치평가 > 투자조합 가치평가 결과조회 | J25: 투자자산 | L25: 신규(현행 없음) | O25: 유무형자산관리 | P25: 회계 > 고정자산 > 유무형자산관리
C26: 종합통계(확정) | D26: ffms > 자펀드 관리 > 종합통계 | G26: 피투자회사 가치평가 결과조회 | H26: risk > 가치평가 > 피투자회사 가치평가 결과조회 | K26: 투자기업 정보 | L26: ffms > 투자기업정보 > 투자기업정보 | O26: 감가상각비처리 | P26: 회계 > 고정자산 > 감가상각비처리 | Q26: 기존 | V26: 신규
B27: 투자기업정보 | D27: ffms > 투자기업정보 | G27: 자펀드 투자자산 및 거래내역 조회 | H27: risk > 가치평가 > 자펀드 투자자산 및 거래내역 조회 | K27: 투자기업 고용현황(반기별) | L27: ffms > 투자기업정보 > 투자기업 고용현황보고 | N27: 자금관리 | P27: 회계 > 자금관리 | Q27: 관리자 | V27: 관리자
C28: 투자기업정보(통합) | D28: ffms > 투자기업정보 > 투자기업정보 / risk > 기업정보 > 투자기업정보(전체) | G28: 예외사항레포트 | H28: risk > 가치평가 > 예외사항레포트 | K28: 투자기업 재무정보 | L28: 신규(현행 없음) | O28: 계좌관리 | P28: 회계 > 자금관리 > 계좌관리
C29: 투자기업명세서(통합) | D29: ffms > 투자기업정보 > 투자기업정보(전체) | G29: 평가시점 데이터 확인 | H29: risk > 가치평가 > 평가시점 데이터 확인 | K29: 투자기업 주주명부 | L29: 신규(현행 없음) | O29: 계좌잔액 | P29: 회계 > 자금관리 > 계좌잔액 | R29: 시스템 관리 | W29: 사용자·권한 관리
C30: 투자기업고용현황(통합) | D30: ffms > 투자기업정보 > 투자기업 고용현황보고 | G30: Portfolio Report | H30: risk > 가치평가 > Portfolio Report | K30: 투자자금 실사보고 | L30: ffms > 모니터링 > 투자금 실사보고 | O30: 자금일보 | P30: 회계 > 자금관리 > 자금일보 | S30: 공통코드 관리 | T30: 관리자 > 시스템 관리 > 공통코드 관리 / ffms > 관리자 > 공통코드관리 / risk > 관리자 > 공통코드 관리 | X30: 권한관리 | Y30: S0_102_권한관리.html
C31: 전체 투자실적 | D31: ffms > 투자기업정보 > 전체 투자실적 | G31: 투자기업별(계약별) IRR | H31: risk > 가치평가 > 투자기업별(계약별) IRR | K31: 프로젝트 정보 | L31: 신규(현행 없음) | O31: 출자금현황 정보관리 | P31: 회계 > 자금관리 > 출자금현황 정보관리 | S31: 메뉴 관리 | T31: 관리자 > 시스템 관리 > 메뉴 관리 / ffms > 관리자 > 메뉴관리 / risk > 관리자 > 메뉴 관리 | X31: 사용자관리 | Y31: S0_101_사용자관리.html
C32: 투자실적현황(투자기업) | D32: ffms > 투자기업정보 > 투자실적 현황(투자기업) | G32: 투자기업별 IRR | H32: risk > 가치평가 > 투자기업별 IRR | K32: 투자기업 투심현황 | L32: ffms > 사후보고관리 > 투자심의 관리 | N32: 농식품경영체 | P32: 회계 > 농식품경영체 | S32: 도움말 관리 | T32: 관리자 > 시스템 관리 > 도움말 관리 / risk > 관리자 > 도움말 관리 | X32: 사용자 초대(운용사) | Y32: S0_103_사용자초대_운용사.html
C33: 투자금 회수현황 | D33: ffms > 투자기업정보 > 투자및회수상세정보 | G33: 자펀드별 IRR | H33: risk > 가치평가 > 자펀드별 IRR | K33: 투자 약정정보 | L33: 신규(현행 없음) | O33: 경영체 정보 조회 | P33: 회계 > 농식품경영체 > 경영체 정보 조회 | R33: 사용자 관리 | W33: 시스템 관리
C34: 우수투자기업 관리 | D34: 신규(현행 없음) | K34: 투자 거래정보 | L34: ffms > 투자기업정보 > 투자및회수상세정보 / risk > 가치평가 > 자펀드 투자자산 및 거래내역 조회 | O34: IR정보 조회 | P34: 회계 > 농식품경영체 > IR정보 조회 | S34: 사용자 관리 | T34: 관리자 > 사용자 관리 > 사용자 관리 / ffms > 관리자 > 사용자관리 / brief > 관리자 > 사용자관리 | X34: 프로그램관리 | Y34: S0_108_프로그램관리.html
B35: 운용사 모니터링 | D35: ffms > 모니터링 | J35: 월간보고조회 | L35: report > 월간보고조회 | N35: 설정 | P35: 회계 > 설정 | S35: 사용자 권한 관리 | T35: 관리자 > 사용자 관리 > 사용자 권한 관리 / risk > 관리자 > 사용자권한 관리 / brief > 관리자 > 사용자권한관리 / 사용자조합권한관리 | X35: 메뉴관리 | Y35: S0_105_메뉴관리.html
C36: 운용사 명세서 | D36: ffms > 투자기업정보 > 운용사별 재무제표 (검토 필요) | K36: 조합별 월간보고 현황 | L36: report > 월간보고조회 > 조합별 월간보고 현황 | O36: 휴일관리 | P36: 회계 > 설정 > 휴일관리 | R36: 외부연동 | X36: 코드관리 | Y36: S0_106_코드관리.html
C37: 운용사 재무정보 조회 | D37: ffms > 모니터링 > 운용사 재무정보 조회 / risk > 기초정보 > 운용사 재무정보 비교 조회 | J37: 반기보고조회 | L37: report > 반기보고조회 | O37: 회계거래처관리 | P37: 회계 > 설정 > 회계거래처관리 | S37: 자펀드 코드관리(운용사ERP&수탁기관) | T37: 관리자 > 외부연동 > 자펀드 코드관리(운용사ERP&수탁기관) | W37: 감사·기록
C38: 투자금 실사보고 조회 | D38: ffms > 모니터링 > 투자금 실사보고 | K38: 조합별 반기보고 현황 | L38: report > 반기보고조회 > 조합별 반기보고 현황 | S38: 연계 모니터링(API) | T38: 관리자 > 외부연동 > 연계 모니터링(API) | X38: 권한 변경이력 | Y38: S0_107_권한변경이력.html
C39: 사후관리기록 관리 | D39: ffms > 모니터링 > 사후관리기록 | J39: 실물검증 | L39: report > 실물검증 | S39: 자펀드 보고 양식관리(운용사ERP) | T39: 관리자 > 외부연동 > 자펀드 보고 양식관리(운용사ERP) / ffms > 사후보고관리 > 보고양식관리 | X39: 감사로그 | Y39: S0_104_감사로그.html
C40: 관리보수/성과보수 조회 | D40: ffms > 모니터링 > 관리보수관리 | K40: 조합별 실물검증 결과 보고 | L40: report > 실물검증 > 조합별 실물검증 결과 보고 | R40: 보안
C41: 자펀드 전체 보고현황 | D41: ffms > 모니터링 > 전체 보고현황 | J41: 파일 | L41: report > 업로드 | S41: 개인정보 접속관리 | T41: 관리자 > 보안 > 개인정보 접속관리
...
